<?xml version="1.0" encoding="utf-8"?>
<!-- This URDF was automatically created by SolidWorks to URDF Exporter! Originally created by Stephen Brawner (brawner@gmail.com) 
     Commit Version: 1.6.0-4-g7f85cfe  Build Version: 1.6.7995.38578
     For more information, please see http://wiki.ros.org/sw_urdf_exporter -->
<robot name="mdoger7">
  <link name="base_link">
    <inertial>
      <origin xyz="0.00010106 -0.00001449 0.04965637" rpy="0 0 0" />
      <mass value="3.08231817" />
      <inertia ixx="0.02256965" ixy="0.00000582" ixz="0.00000409" iyy="0.06340830" iyz="0.00000161" izz="0.07738183" />
    </inertial>
    <visual>
      <origin xyz="0 0 0" rpy="0 0 0" />
      <geometry>
        <mesh filename="package://mdoger7/meshes/base_link.STL" />
      </geometry>
      <material name="">
        <color rgba="1 1 1 1" />
      </material>
    </visual>
    <collision>
      <origin xyz="0 0 0" rpy="0 0 0" />
      <geometry>
        <mesh filename="package://mdoger7/meshes/base_link.STL" />
      </geometry>
    </collision>
  </link>
  <link name="lf1">
    <inertial>
      <origin xyz="-0.01516373 -0.00001750 0.06414061" rpy="0 0 0" />
      <mass value="0.27830200" />
      <inertia ixx="0.00036169" ixy="-0.00000013" ixz="-0.00002051" iyy="0.00025180" iyz="-0.00000002" izz="0.00018538" />
    </inertial>
    <visual>
      <origin xyz="0 0 0" rpy="0 0 0" />
      <geometry>
        <mesh filename="package://mdoger7/meshes/lf1.STL" />
      </geometry>
      <material name="">
        <color rgba="1 1 1 1" />
      </material>
    </visual>
    <collision>
      <origin xyz="0 0 0" rpy="0 0 0" />
      <geometry>
        <mesh filename="package://mdoger7/meshes/lf1.STL" />
      </geometry>
    </collision>
  </link>
  <joint name="lf1_joint" type="revolute">
    <origin xyz="0.2043 0.08 0.05825" rpy="1.5708 0.0011541 1.5708" />
    <parent link="base_link" />
    <child link="lf1" />
    <axis xyz="0 0 -1" />
    <limit lower="-0.174" upper="0.174" effort="100" velocity="1" />
  </joint>
  <link name="lf2">
    <inertial>
      <origin xyz="0.02094234 -0.02074639 0.04952985" rpy="0 0 0" />
      <mass value="0.44448058" />
      <inertia ixx="0.00132496" ixy="-0.00092284" ixz="0.00024164" iyy="0.00133160" iyz="-0.00024008" izz="0.00222455" />
    </inertial>
    <visual>
      <origin xyz="0 0 0" rpy="0 0 0" />
      <geometry>
        <mesh filename="package://mdoger7/meshes/lf2.STL" />
      </geometry>
      <material name="">
        <color rgba="1 1 1 1" />
      </material>
    </visual>
    <collision>
      <origin xyz="0 0 0" rpy="0 0 0" />
      <geometry>
        <mesh filename="package://mdoger7/meshes/lf2.STL" />
      </geometry>
    </collision>
  </link>
  <joint name="lf2_joint" type="revolute">
    <origin xyz="0.0031 0.00000358 0.069" rpy="0 1.5708 0" />
    <parent link="lf1" />
    <child link="lf2" />
    <axis xyz="0 -0.0011541 -1" />
    <limit lower="-0.523" upper="0.523" effort="100" velocity="1" />
  </joint>
  <link name="lf3">
    <inertial>
      <origin xyz="-0.05292001 -0.05290891 0.00005762" rpy="0 0 0" />
      <mass value="0.03645433" />
      <inertia ixx="0.00008241" ixy="0.00007839" ixz="-0.00000009" iyy="0.00008271" iyz="-0.00000009" izz="0.00016406" />
    </inertial>
    <visual>
      <origin xyz="0 0 0" rpy="0 0 0" />
      <geometry>
        <mesh filename="package://mdoger7/meshes/lf3.STL" />
      </geometry>
      <material name="">
        <color rgba="1 1 1 1" />
      </material>
    </visual>
    <collision>
      <origin xyz="0 0 0" rpy="0 0 0" />
      <geometry>
        <mesh filename="package://mdoger7/meshes/lf3.STL" />
      </geometry>
    </collision>
  </link>
  <joint name="lf3_joint" type="revolute">
    <origin xyz="0.14849 -0.14838 0.099471" rpy="0 0 0" />
    <parent link="lf2" />
    <child link="lf3" />
    <axis xyz="0 0.0011541 1" />
    <limit lower="-0.523" upper="0.523" effort="100" velocity="1" />
  </joint>
  <link name="lf_foot">
    <inertial>
      <origin xyz="0 0.00002498 0.00028212" rpy="0 0 0" />
      <mass value="0.03108367" />
      <inertia ixx="0.00000596" ixy="0" ixz="0" iyy="0.00000576" iyz="0" izz="0.00000548" />
    </inertial>
    <visual>
      <origin xyz="0 0 0" rpy="0 0 0" />
      <geometry>
        <mesh filename="package://mdoger7/meshes/lf_foot.STL" />
      </geometry>
      <material name="">
        <color rgba="1 1 1 1" />
      </material>
    </visual>
    <collision>
      <origin xyz="0 0 0" rpy="0 0 0" />
      <geometry>
        <mesh filename="package://mdoger7/meshes/lf_foot.STL" />
      </geometry>
    </collision>
  </link>
  <joint name="lf_foot_joint" type="fixed">
    <origin xyz="-0.14426 -0.14581 0.00072578" rpy="1.5716 0.0008161 2.3562" />
    <parent link="lf3" />
    <child link="lf_foot" />
    <axis xyz="0 0 0" />
  </joint>
  <link name="rf1">
    <inertial>
      <origin xyz="-0.01516373 0.00001750 -0.06414061" rpy="0 0 0" />
      <mass value="0.27830200" />
      <inertia ixx="0.00036169" ixy="0.0000013" ixz="0.00002051" iyy="0.00025180" iyz="-0.00000002" izz="0.00018538" />
    </inertial>
    <visual>
      <origin xyz="0 0 0" rpy="0 0 0" />
      <geometry>
        <mesh filename="package://mdoger7/meshes/rf1.STL" />
      </geometry>
      <material name="">
        <color rgba="1 1 1 1" />
      </material>
    </visual>
    <collision>
      <origin xyz="0 0 0" rpy="0 0 0" />
      <geometry>
        <mesh filename="package://mdoger7/meshes/rf1.STL" />
      </geometry>
    </collision>
  </link>
  <joint name="rf1_joint" type="revolute">
    <origin xyz="0.2043 -0.08 0.05825" rpy="1.5708 -0.0011541 -1.5708" />
    <parent link="base_link" />
    <child link="rf1" />
    <axis xyz="0 0 1" />
    <limit lower="-0.174" upper="0.174" effort="100" velocity="1" />
  </joint>
  <link name="rf2">
    <inertial>
      <origin xyz="-0.02094116 -0.02085936 0.04948201" rpy="0 0 0" />
      <mass value="0.44447934" />
      <inertia ixx="0.00132484" ixy="0.00092328" ixz="-0.00023951" iyy="0.00133038" iyz="-0.00023802" izz="0.00222543" />
    </inertial>
    <visual>
      <origin xyz="0 0 0" rpy="0 0 0" />
      <geometry>
        <mesh filename="package://mdoger7/meshes/rf2.STL" />
      </geometry>
      <material name="">
        <color rgba="1 1 1 1" />
      </material>
    </visual>
    <collision>
      <origin xyz="0 0 0" rpy="0 0 0" />
      <geometry>
        <mesh filename="package://mdoger7/meshes/rf2.STL" />
      </geometry>
    </collision>
  </link>
  <joint name="rf2_joint" type="revolute">
    <origin xyz="0.0031 -0.00000358 -0.069" rpy="0 1.5708 0" />
    <parent link="rf1" />
    <child link="rf2" />
    <axis xyz="0 0.0011541 -1" />
    <limit lower="-0.523" upper="0.523" effort="100" velocity="1" />
  </joint>
  <link name="rf3">
    <inertial>
      <origin xyz="0.05290887 -0.05292004 -0.00006452" rpy="0 0 0" />
      <mass value="0.03645433" />
      <inertia ixx="0.00008272" ixy="-0.00007839" ixz="-0.00000009" iyy="0.00008241" iyz="0.00000009" izz="0.00016406" />
    </inertial>
    <visual>
      <origin xyz="0 0 0" rpy="0 0 0" />
      <geometry>
        <mesh filename="package://mdoger7/meshes/rf3.STL" />
      </geometry>
      <material name="">
        <color rgba="1 1 1 1" />
      </material>
    </visual>
    <collision>
      <origin xyz="0 0 0" rpy="0 0 0" />
      <geometry>
        <mesh filename="package://mdoger7/meshes/rf3.STL" />
      </geometry>
    </collision>
  </link>
  <joint name="rf3_joint" type="revolute">
    <origin xyz="-0.14849 -0.14861 0.099129" rpy="0 0 0" />
    <parent link="rf2" />
    <child link="rf3" />
    <axis xyz="0 -0.0011541 1" />
    <limit lower="-0.523" upper="0.523" effort="100" velocity="1" />
  </joint>
  <link name="rf_foot">
    <inertial>
      <origin xyz="0 -0.00002497 0.00028212" rpy="0 0 0" />
      <mass value="0.03108367" />
      <inertia ixx="0.00000596" ixy="0" ixz="0" iyy="0.00000576" iyz="0" izz="0.00000548" />
    </inertial>
    <visual>
      <origin xyz="0 0 0" rpy="0 0 0" />
      <geometry>
        <mesh filename="package://mdoger7/meshes/rf_foot.STL" />
      </geometry>
      <material name="">
        <color rgba="1 1 1 1" />
      </material>
    </visual>
    <collision>
      <origin xyz="0 0 0" rpy="0 0 0" />
      <geometry>
        <mesh filename="package://mdoger7/meshes/rf_foot.STL" />
      </geometry>
    </collision>
  </link>
  <joint name="rf_foot_joint" type="fixed">
    <origin xyz="0.14496 -0.14496 -0.0001673" rpy="-1.57 -0.0008161 0.7854" />
    <parent link="rf3" />
    <child link="rf_foot" />
    <axis xyz="0 0 0" />
  </joint>
  <link name="lb1">
    <inertial>
      <origin xyz="-0.01516373 -0.00001750 -0.06414061" rpy="0 0 0" />
      <mass value="0.27830200" />
      <inertia ixx="0.00036169" ixy="-0.00000013" ixz="0.00002051" iyy="0.00025180" iyz="0.00000002" izz="0.00018538" />
    </inertial>
    <visual>
      <origin xyz="0 0 0" rpy="0 0 0" />
      <geometry>
        <mesh filename="package://mdoger7/meshes/lb1.STL" />
      </geometry>
      <material name="">
        <color rgba="1 1 1 1" />
      </material>
    </visual>
    <collision>
      <origin xyz="0 0 0" rpy="0 0 0" />
      <geometry>
        <mesh filename="package://mdoger7/meshes/lb1.STL" />
      </geometry>
    </collision>
  </link>
  <joint name="lb1_joint" type="revolute">
    <origin xyz="-0.2043 0.08 0.05825" rpy="1.5708 0.0011541 1.5708" />
    <parent link="base_link" />
    <child link="lb1" />
    <axis xyz="0 0 1" />
    <limit lower="-0.174" upper="0.174" effort="100" velocity="1" />
  </joint>
  <link name="lb2">
    <inertial>
      <origin xyz="0.02084748 -0.02084124 0.04952996" rpy="0 0 0" />
      <mass value="0.44448058" />
      <inertia ixx="0.00132934" ixy="-0.00092322" ixz="0.00024057" iyy="0.00132645" iyz="-0.00024115" izz="0.00222378" />
    </inertial>
    <visual>
      <origin xyz="0 0 0" rpy="0 0 0" />
      <geometry>
        <mesh filename="package://mdoger7/meshes/lb2.STL" />
      </geometry>
      <material name="">
        <color rgba="1 1 1 1" />
      </material>
    </visual>
    <collision>
      <origin xyz="0 0 0" rpy="0 0 0" />
      <geometry>
        <mesh filename="package://mdoger7/meshes/lb2.STL" />
      </geometry>
    </collision>
  </link>
  <joint name="lb2_joint" type="revolute">
    <origin xyz="0.0031 0.00000358 -0.069" rpy="0 1.5708 0" />
    <parent link="lb1" />
    <child link="lb2" />
    <axis xyz="0 -0.0011541 -1" />
    <limit lower="-0.523" upper="0.523" effort="100" velocity="1" />
  </joint>
  <link name="lb3">
    <inertial>
      <origin xyz="-0.05292005 -0.05290888 0.00005762" rpy="0 0 0" />
      <mass value="0.03645433" />
      <inertia ixx="0.00008241" ixy="0.00007839" ixz="-0.00000009" iyy="0.00008272" iyz="-0.00000009" izz="0.00016406" />
    </inertial>
    <visual>
      <origin xyz="0 0 0" rpy="0 0 0" />
      <geometry>
        <mesh filename="package://mdoger7/meshes/lb3.STL" />
      </geometry>
      <material name="">
        <color rgba="1 1 1 1" />
      </material>
    </visual>
    <collision>
      <origin xyz="0 0 0" rpy="0 0 0" />
      <geometry>
        <mesh filename="package://mdoger7/meshes/lb3.STL" />
      </geometry>
    </collision>
  </link>
  <joint name="lb3_joint" type="revolute">
    <origin xyz="0.14849 -0.14838 0.099471" rpy="0 0 0" />
    <parent link="lb2" />
    <child link="lb3" />
    <axis xyz="0 0.0011541 1" />
    <limit lower="-0.523" upper="0.523" effort="100" velocity="1" />
  </joint>
  <link name="lb_foot">
    <inertial>
      <origin xyz="0 -0.00002497 0.00028212" rpy="0 0 0" />
      <mass value="0.03108367" />
      <inertia ixx="0.00000596" ixy="0" ixz="0" iyy="0.00000576" iyz="0" izz="0.00000548" />
    </inertial>
    <visual>
      <origin xyz="0 0 0" rpy="0 0 0" />
      <geometry>
        <mesh filename="package://mdoger7/meshes/lb_foot.STL" />
      </geometry>
      <material name="">
        <color rgba="1 1 1 1" />
      </material>
    </visual>
    <collision>
      <origin xyz="0 0 0" rpy="0 0 0" />
      <geometry>
        <mesh filename="package://mdoger7/meshes/lb_foot.STL" />
      </geometry>
    </collision>
  </link>
  <joint name="lb_foot_joint" type="fixed">
    <origin xyz="-0.14496 -0.14496 0.0001673" rpy="1.5716 0.0008161 2.3562" />
    <parent link="lb3" />
    <child link="lb_foot" />
    <axis xyz="0 0 0" />
  </joint>
  <link name="rb1">
    <inertial>
      <origin xyz="-0.01516373 0.00001750 0.06414061" rpy="0 0 0" />
      <mass value="0.27830200" />
      <inertia ixx="0.00036169" ixy="0.00000013" ixz="-0.00002051" iyy="0.00025180" iyz="0.00000002" izz="0.00018538" />
    </inertial>
    <visual>
      <origin xyz="0 0 0" rpy="0 0 0" />
      <geometry>
        <mesh filename="package://mdoger7/meshes/rb1.STL" />
      </geometry>
      <material name="">
        <color rgba="1 1 1 1" />
      </material>
    </visual>
    <collision>
      <origin xyz="0 0 0" rpy="0 0 0" />
      <geometry>
        <mesh filename="package://mdoger7/meshes/rb1.STL" />
      </geometry>
    </collision>
  </link>
  <joint name="rb1_joint" type="revolute">
    <origin xyz="-0.2043 -0.08 0.05825" rpy="1.5708 -0.0011541 -1.5708" />
    <parent link="base_link" />
    <child link="rb1" />
    <axis xyz="0 0 -1" />
    <limit lower="-0.174" upper="0.174" effort="100" velocity="1" />
  </joint>
  <link name="rb2">
    <inertial>
      <origin xyz="-0.02085520 -0.02094531 0.04948143" rpy="0 0 0" />
      <mass value="0.44447934" />
      <inertia ixx="0.00132817" ixy="0.00092440" ixz="-0.00023851" iyy="0.00132626" iyz="-0.00023895" izz="0.00222465" />
    </inertial>
    <visual>
      <origin xyz="0 0 0" rpy="0 0 0" />
      <geometry>
        <mesh filename="package://mdoger7/meshes/rb2.STL" />
      </geometry>
      <material name="">
        <color rgba="1 1 1 1" />
      </material>
    </visual>
    <collision>
      <origin xyz="0 0 0" rpy="0 0 0" />
      <geometry>
        <mesh filename="package://mdoger7/meshes/rb2.STL" />
      </geometry>
    </collision>
  </link>
  <joint name="rb2_joint" type="revolute">
    <origin xyz="0.0031 -0.00000358 0.069" rpy="0 1.5708 0" />
    <parent link="rb1" />
    <child link="rb2" />
    <axis xyz="0 0.0011541 -1" />
    <limit lower="-0.523" upper="0.523" effort="100" velocity="1" />
  </joint>
  <link name="rb3">
    <inertial>
      <origin xyz="0.05292001 -0.05290891 -0.00005762" rpy="0 0 0" />
      <mass value="0.03645433" />
      <inertia ixx="0.00008241" ixy="-0.00007893" ixz="-0.00000009" iyy="0.00008271" iyz="0.00000009" izz="0.00016406" />
    </inertial>
    <visual>
      <origin xyz="0 0 0" rpy="0 0 0" />
      <geometry>
        <mesh filename="package://mdoger7/meshes/rb3.STL" />
      </geometry>
      <material name="">
        <color rgba="1 1 1 1" />
      </material>
    </visual>
    <collision>
      <origin xyz="0 0 0" rpy="0 0 0" />
      <geometry>
        <mesh filename="package://mdoger7/meshes/rb3.STL" />
      </geometry>
    </collision>
  </link>
  <joint name="rb3_joint" type="revolute">
    <origin xyz="-0.14849 -0.14861 0.099129" rpy="0 0 0" />
    <parent link="rb2" />
    <child link="rb3" />
    <axis xyz="0 -0.0011541 1" />
    <limit lower="-0.523" upper="0.523" effort="100" velocity="1" />
  </joint>
  <link name="rb_foot">
    <inertial>
      <origin xyz="0 -0.00002497 0.00028212" rpy="0 0 0" />
      <mass value="0.03108367" />
      <inertia ixx="0.00000596" ixy="0" ixz="0" iyy="0.00000576" iyz="0" izz="0.00000548" />
    </inertial>
    <visual>
      <origin xyz="0 0 0" rpy="0 0 0" />
      <geometry>
        <mesh filename="package://mdoger7/meshes/rb_foot.STL" />
      </geometry>
      <material name="">
        <color rgba="1 1 1 1" />
      </material>
    </visual>
    <collision>
      <origin xyz="0 0 0" rpy="0 0 0" />
      <geometry>
        <mesh filename="package://mdoger7/meshes/rb_foot.STL" />
      </geometry>
    </collision>
  </link>
  <joint name="rb_foot_joint" type="fixed">
    <origin xyz="0.14496 -0.14496 -0.0001673" rpy="-1.57 -0.0008161 0.7854" />
    <parent link="rb3" />
    <child link="rb_foot" />
    <axis xyz="0 0 0" />
  </joint>
</robot>